
Training Set Score : 100.0 %
Test Set Score : 100.0 %
Traceback (most recent call last):
  File "C:\Users\B00460204\AppData\Local\Packages\PythonSoftwareFoundation.Python.3.10_qbz5n2kfra8p0\LocalCache\local-packages\Python310\site-packages\joblib\parallel.py", line 822, in dispatch_one_batch
    tasks = self._ready_batches.get(block=False)
  File "C:\Program Files\WindowsApps\PythonSoftwareFoundation.Python.3.10_3.10.752.0_x64__qbz5n2kfra8p0\lib\queue.py", line 168, in get
    raise Empty
_queue.Empty
During handling of the above exception, another exception occurred:
Traceback (most recent call last):
  File "C:\Users\B00460204\OneDrive - Ulster University\Phd - FPGA acceleration in genomics\2020-21 MainResearch\Seed_generation\rapid-SMEM\Rapid-SMEM\gnb_seed_generation_2\main.py", line 132, in <module>
    main()
  File "C:\Users\B00460204\OneDrive - Ulster University\Phd - FPGA acceleration in genomics\2020-21 MainResearch\Seed_generation\rapid-SMEM\Rapid-SMEM\gnb_seed_generation_2\main.py", line 106, in main
    for i, score in enumerate(cross_validate(model, X_test,y_test, cv=3)["test_score"]):
  File "C:\Users\B00460204\AppData\Local\Packages\PythonSoftwareFoundation.Python.3.10_qbz5n2kfra8p0\LocalCache\local-packages\Python310\site-packages\sklearn\model_selection\_validation.py", line 267, in cross_validate
    results = parallel(
  File "C:\Users\B00460204\AppData\Local\Packages\PythonSoftwareFoundation.Python.3.10_qbz5n2kfra8p0\LocalCache\local-packages\Python310\site-packages\joblib\parallel.py", line 1043, in __call__
    if self.dispatch_one_batch(iterator):
  File "C:\Users\B00460204\AppData\Local\Packages\PythonSoftwareFoundation.Python.3.10_qbz5n2kfra8p0\LocalCache\local-packages\Python310\site-packages\joblib\parallel.py", line 833, in dispatch_one_batch
    islice = list(itertools.islice(iterator, big_batch_size))
  File "C:\Users\B00460204\AppData\Local\Packages\PythonSoftwareFoundation.Python.3.10_qbz5n2kfra8p0\LocalCache\local-packages\Python310\site-packages\sklearn\model_selection\_validation.py", line 267, in <genexpr>
    results = parallel(
  File "C:\Users\B00460204\AppData\Local\Packages\PythonSoftwareFoundation.Python.3.10_qbz5n2kfra8p0\LocalCache\local-packages\Python310\site-packages\sklearn\model_selection\_split.py", line 340, in split
    for train, test in super().split(X, y, groups):
  File "C:\Users\B00460204\AppData\Local\Packages\PythonSoftwareFoundation.Python.3.10_qbz5n2kfra8p0\LocalCache\local-packages\Python310\site-packages\sklearn\model_selection\_split.py", line 86, in split
    for test_index in self._iter_test_masks(X, y, groups):
  File "C:\Users\B00460204\AppData\Local\Packages\PythonSoftwareFoundation.Python.3.10_qbz5n2kfra8p0\LocalCache\local-packages\Python310\site-packages\sklearn\model_selection\_split.py", line 709, in _iter_test_masks
    test_folds = self._make_test_folds(X, y)
  File "C:\Users\B00460204\AppData\Local\Packages\PythonSoftwareFoundation.Python.3.10_qbz5n2kfra8p0\LocalCache\local-packages\Python310\site-packages\sklearn\model_selection\_split.py", line 671, in _make_test_folds
    raise ValueError(
ValueError: n_splits=3 cannot be greater than the number of members in each class.