Making rotations
Building suffix array column
Building BWT
Populating FM index character counts
Generating k-length seeds
Cannot find data_sets directory, creating one...
Traceback (most recent call last):
  File "C:\Users\B00460204\OneDrive - Ulster University\Phd - FPGA acceleration in genomics\2020-21 MainResearch\Seed_generation\rapid-SMEM\Rapid-SMEM\gnb_seed_generation\main.py", line 58, in generate_index
    index.to_csv("data_sets/indexed_reference.csv", index = False)
  File "C:\Users\B00460204\AppData\Local\Packages\PythonSoftwareFoundation.Python.3.10_qbz5n2kfra8p0\LocalCache\local-packages\Python310\site-packages\pandas\core\generic.py", line 3563, in to_csv
    return DataFrameRenderer(formatter).to_csv(
  File "C:\Users\B00460204\AppData\Local\Packages\PythonSoftwareFoundation.Python.3.10_qbz5n2kfra8p0\LocalCache\local-packages\Python310\site-packages\pandas\io\formats\format.py", line 1180, in to_csv
    csv_formatter.save()
  File "C:\Users\B00460204\AppData\Local\Packages\PythonSoftwareFoundation.Python.3.10_qbz5n2kfra8p0\LocalCache\local-packages\Python310\site-packages\pandas\io\formats\csvs.py", line 241, in save
    with get_handle(
  File "C:\Users\B00460204\AppData\Local\Packages\PythonSoftwareFoundation.Python.3.10_qbz5n2kfra8p0\LocalCache\local-packages\Python310\site-packages\pandas\io\common.py", line 789, in get_handle
    handle = open(
PermissionError: [Errno 13] Permission denied: 'data_sets/indexed_reference.csv'
During handling of the above exception, another exception occurred:
Traceback (most recent call last):
  File "C:\Users\B00460204\OneDrive - Ulster University\Phd - FPGA acceleration in genomics\2020-21 MainResearch\Seed_generation\rapid-SMEM\Rapid-SMEM\gnb_seed_generation\main.py", line 179, in <module>
    main()
  File "C:\Users\B00460204\OneDrive - Ulster University\Phd - FPGA acceleration in genomics\2020-21 MainResearch\Seed_generation\rapid-SMEM\Rapid-SMEM\gnb_seed_generation\main.py", line 145, in main
    generate_index(reference_genome, count)
  File "C:\Users\B00460204\OneDrive - Ulster University\Phd - FPGA acceleration in genomics\2020-21 MainResearch\Seed_generation\rapid-SMEM\Rapid-SMEM\gnb_seed_generation\main.py", line 61, in generate_index
    os.makedirs('data_sets')
  File "C:\Program Files\WindowsApps\PythonSoftwareFoundation.Python.3.10_3.10.752.0_x64__qbz5n2kfra8p0\lib\os.py", line 225, in makedirs
    mkdir(name, mode)
FileExistsError: [WinError 183] Cannot create a file when that file already exists: 'data_sets'